<?xml version="1.0"?>

<robot name="KillerRover2000">
  
  <!-- *************************************************** -->
  <!-- ***************** Kinematic Chain ***************** -->
  <!-- *************************************************** -->
  <!-- Note the 'origin' tag in the joints defines the
       shift and reorientation before the continuous joint
       rotates around the 'axis'. -->


  <!-- Locate the base plate at the world origin. -->
  <joint name="place" type="fixed">
    <parent link="world"/>
    <child  link="baseplate"/>
    <origin xyz="0 0 0" rpy="0 0 0"/>
  </joint>

  <!-- Shift across the base plate to the base motor. -->
  <joint name="baseplate" type="fixed">
    <parent link="baseplate"/>
    <child  link="motor0"/>
    <origin xyz="0 0 0" rpy="0 0 0"/>
  </joint>

  <!-- Motor0 -->
  <joint name="theta0" type="continuous">
    <parent link="motor0"/>
    <child  link="basecylinder"/>
    <origin xyz="0 0 0" rpy="0 0 0"/>
    <axis   xyz="0 0 1"/>
  </joint>

  <!-- Base cylinder link -->
  <joint name="basecylinder" type="fixed">
    <parent link="basecylinder"/>
    <child  link="motor1link"/>
    <origin xyz="0 0 0.0127" rpy="0 0 0"/>
  </joint>

  <!-- Link to motor1 -->
  <joint name="motor1link" type="fixed">
    <parent link="motor1link"/>
    <child  link="motor1"/>
    <origin xyz="0.0225 0.017 0.0902" rpy="0 0 0"/>
  </joint>

  <!-- Motor1 -->
  <joint name="theta1" type="continuous">
    <parent link="motor1"/>
    <child  link="motor2link"/>
    <origin xyz="0 0 0" rpy="0 0 0"/>
    <axis   xyz="1 0 0"/>
  </joint>

  <!-- Link to motor2 -->
  <joint name="motor2link" type="fixed">
    <parent link="motor2link"/>
    <child  link="motor2"/>
    <origin xyz="0.0574 0.396 0.0" rpy="0 0 0"/>
  </joint>

  <!-- Motor2 -->
  <joint name="theta2" type="continuous">
    <parent link="motor2"/>
    <child  link="motor3link"/>
    <origin xyz="0 0 0" rpy="0 0 0"/>
    <axis   xyz="1 0 0"/>
  </joint>

  <!-- Link to motor3 -->
  <joint name="motor3link" type="fixed">
    <parent link="motor3link"/>
    <child  link="motor3"/>
    <origin xyz="-0.0574 0.396 0.0" rpy="0 0 0"/>
  </joint>

  <!-- Motor3 -->
  <joint name="theta3" type="continuous">
    <parent link="motor3"/>
    <child  link="motor4link"/>
    <origin xyz="0 0 0" rpy="0 0 0"/>
    <axis   xyz="1 0 0"/>
  </joint>

  <!-- Link to motor4 -->
  <joint name="motor4link" type="fixed">
    <parent link="motor4link"/>
    <child  link="motor4"/>
    <origin xyz="0 0.1535 0.0574" rpy="0 0 0"/>
  </joint>

  <!-- Motor4 -->
  <joint name="theta4" type="continuous">
    <parent link="motor4"/>
    <child  link="tiplink"/>
    <origin xyz="0 0 0" rpy="0 0 0"/>
    <axis   xyz="0 0 1"/>
  </joint>

  <!-- Link to tip -->
  <joint name="tiplink" type="fixed">
    <parent link="tiplink"/>
    <child  link="tip"/>
    <origin xyz="0 0.1275 0" rpy="0 0 0"/>
  </joint>
  
  <!-- *************************************************** -->
  <!-- *************** Visual Link Elements ************** -->
  <!-- *************************************************** -->
  <!-- Note collada .dae files have better color/texture   -->
  <!-- suppport that STL files.                            -->

  <!-- Colors -->
  <material name="wood">  <color rgba="0.82 0.62 0.04 1"/>  </material>
  <material name="hebi">  <color rgba="0.82 0.06 0.06 1"/>  </material>

  <!-- World can't take a visual element (at least in Gazebo). -->
  <link name="world"/>

  <link name="baseplate">
    <visual>
      <origin xyz = "0 0 -0.025" rpy = "0 0 0"/>
      <geometry>
        <box size="0.1778 0.1778 0.05"/>
      </geometry>
      <material name="wood"/>
    </visual>
  </link>

  <link name="motor0">
    <visual>
      <origin xyz = "0 0 0" rpy = "0 0 0"/>
      <geometry>
        <sphere radius="0.000001"/>
      </geometry>
      <material name="hebi"/>
    </visual>
  </link>

  <link name="basecylinder">
    <visual>
      <origin xyz = "0 0 0.00635" rpy = "0 0 0"/>
      <geometry>
        <cylinder length="0.0127" radius="0.2286"/>
      </geometry>
      <material name="hebi"/>
    </visual>
  </link>

  <link name="motor1link">
    <visual>
      <origin xyz = "0.0225 0.017 0.0451" rpy = "0 0 0"/>
      <geometry>
        <cylinder length="0.0902" radius="0.0254"/>
      </geometry>
      <material name="wood"/>
    </visual>
  </link>

  <link name="motor1">
    <visual>
      <origin xyz = "0 0 0" rpy = "0 0 0"/>
      <geometry>
        <sphere radius="0.025"/>
      </geometry>
      <material name="hebi"/>
    </visual>
  </link>

  <link name="motor2link">
    <visual>
      <origin xyz = "0 0.198 0" rpy = "1.5708 0 0"/>
      <geometry>
        <cylinder length="0.396" radius="0.016"/>
      </geometry>
      <material name="wood"/>
    </visual>
  </link>

  <link name="motor2">
    <visual>
      <origin xyz = "-0.025 0 0" rpy = "0 1.5708 0"/>
      <geometry>
        <cylinder length="0.1" radius="0.02"/>
      </geometry>
      <material name="hebi"/>
    </visual>
  </link>

  <link name="motor3link">
    <visual>
      <origin xyz = "0 0.198 0" rpy = "1.5708 0 0"/>
      <geometry>
        <cylinder length="0.396" radius="0.016"/>
      </geometry>
      <material name="wood"/>
    </visual>
  </link>

  <link name="motor3">
    <visual>
      <origin xyz = "0.025 0 0" rpy = "0 1.5708 0"/>
      <geometry>
        <cylinder length="0.1" radius="0.02"/>
      </geometry>
      <material name="hebi"/>
    </visual>
  </link>

  <link name="motor4link">
    <visual>
      <origin xyz = "0 0.07675 0" rpy = "1.5708 0 0"/>
      <geometry>
        <cylinder length="0.1535" radius="0.016"/>
      </geometry>
      <material name="wood"/>
    </visual>
  </link>

  <link name="motor4">
    <visual>
      <origin xyz = "0 0 -0.03" rpy = "0 0 0"/>
      <geometry>
        <cylinder length="0.1" radius="0.02"/>
      </geometry>
      <material name="hebi"/>
    </visual>
  </link>
  
  <link name="tiplink">
    <visual>
      <origin xyz = "0 0.06375 0" rpy = "1.5708 0 0"/>
      <geometry>
        <cylinder length="0.1275" radius="0.016"/>
      </geometry>
      <material name="wood"/>
    </visual>
  </link>

  <link name="tip"/>

</robot>
